Workbook

Sheet Resumen P.P.
C3: MILLHOUSE MEXICO
C4: CÁLCULO DE PAGOS PROVISIONALES MENSUALES
C5: IMPUESTO SOBRE LA RENTA (personas morales)
C6: 2025
A8: OP'N. | B8: CONCEPTO | C8: ENERO | D8: ENERO | E8: FEBRERO | F8: MARZO | G8: ABRIL | H8: MAYO | I8: JUNIO | J8: JULIO | K8: AGOSTO | L8: SEPTIEMBRE | M8: OCTUBRE | N8: NOVIEMBRE | O8: DICIEMBRE | P8: ANUAL
A10: DETERMINACIÓN DE LOS INGRESOS
A11: ( = ) | B11: Ventas | C11: ='FACTURAS INGRESOS'!P297 -> 25551509 | D11: =C11 -> 25551509 | E11: ='FACTURAS INGRESOS'!P480 -> 8179265.4 | F11: =ING.MIADMIN!AD241 -> 9532314.5 | G11: HOJA "ING.MIADMIN" | P11: =SUM(D11:O11) -> 43263089
A12: ( - ) | B12: Dev.Reb. Y Desc. Sobre vtas | P12: =SUM(C12:O12) -> 0
A13: ( + ) | B13: Anticipos de Clientes | E13: ='BAL2'!G622 -> 5000 | F13: ='BAL3'!G649 -> 16960 | G13: HOJA "ANT. DE CLIENTES" | P13: =SUM(D13:O13) -> 21960
A14: ( - ) | B14: Cancelacion Anticipos Clientes | P14: =SUM(D14:O14) -> 0
A15: ( + ) | B15: Otros Ingresos | E15: ='BAL01'!G635+'BAL2'!G687 -> 203006.37 | F15: ='BAL3'!G716 -> 0.32 | P15: =SUM(D15:O15) -> 203006.69
A16: ( + ) | B16: Ingreso Venta Activo Fijo | P16: =SUM(D16:O16) -> 0
A17: ( + ) | B17: Intereses a Favor | P17: =SUM(D17:O17) -> 0
A18: ( + ) | B18: Utilidad Cambiaria | C18: ='BAL01'!G682 -> 249688.79 | D18: 552957.23 | E18: ='BAL2'!G782 -> 627113.61 | F18: ='BAL3'!G786 -> 294636.77 | G18: HOJA "UTILIDAD CAMB" | P18: =SUM(D18:O18) -> 1474707.6
A19: ( + ) | B19: Otros Financieros | P19: =SUM(D19:O19) -> 0
A20: ( Ʃ ) | B20: INGRESOS NOMINALES DEL MES | C20: =+C11-C12+C13-C14+C15+C16+C17+C18+C19 -> 25801198 | D20: =+D11-D12+D13-D14+D15+D16+D17+D18+D19 -> 26104466 | E20: =+E11-E12+E13-E14+E15+E16+E17+E18+E19 -> 9014385.4 | F20: =+F11-F12+F13-F14+F15+F16+F17+F18+F19 -> 9843911.6 | G20: =+G11-G12+G13-G14+G15+G16+G17+G18+G19 -> #VALUE! | H20: =+H11-H12+H13-H14+H15+H16+H17+H18+H19 -> 0 | I20: =+I11-I12+I13-I14+I15+I16+I17++I19 -> 0 | J20: =+J11-J12+J13-J14+J15+J16+J17+J18+J19 -> 0 | K20: =+K11-K12+K13-K14+K15+K16+K17+K18+K19 -> 0 | L20: =+L11-L12+L13-L14+L15+L16+L17+L18+L19 -> 0 | M20: =+M11-M12+M13-M14+M15+M16+M17+M18+M19 -> 0 | N20: =+N11-N12+N13-N14+N15+N16+N17+N18+N19 -> 0 | O20: =+O11-O12+O13-O14+O15+O16+O17+O18+O19 -> 0 | P20: =+P11-P12+P13-P14+P15+P16+P17+P18+P19 -> 44962763
A21: ( = ) | B21: INGRESOS ACUMULADOS | C21: =+C20 -> 25801198 | D21: =+D20 -> 26104466 | E21: =+D21+E20 -> 35118852 | F21: =+E21+F20 -> 44962763 | G21: =+F21+G20 -> #VALUE! | H21: =+G21+H20 -> #VALUE! | I21: =+H21+I20 -> #VALUE! | J21: =+I21+J20 -> #VALUE! | K21: =+J21+K20 -> #VALUE! | L21: =+K21+L20 -> #VALUE! | ... O21: =+N21+O20 -> #VALUE! | P21: =+P20 -> 44962763
A24: DETERMINACIÓN DE LA UTILIDAD FISCAL
A25: ( * ) | B25: COEFICIENTE DE UTILIDAD | C25: 0.0715 | D25: 0.0715 | E25: =+C25 -> 0.0715 | F25: 0.3349 | G25: =+F25 -> 0.3349 | H25: =+G25 -> 0.3349 | I25: =+H25 -> 0.3349 | J25: =+I25 -> 0.3349 | K25: =+J25 -> 0.3349 | L25: =+K25 -> 0.3349 | M25: =+L25 -> 0.3349 | N25: =+M25 -> 0.3349 | O25: =+N25 -> 0.3349
A26: ( = ) | B26: UTILIDAD FISCAL | C26: =+C21*C25 -> 1844785.6 | D26: =+D21*D25 -> 1866469.3 | E26: =+E21*E25 -> 2510997.9 | F26: =+F21*F25 -> 15058029 | G26: =+G21*G25-1 -> #VALUE! | H26: =+H21*H25-1 -> #VALUE! | I26: =+I21*I25 -> #VALUE! | J26: =+J21*J25 -> #VALUE! | K26: =+K21*K25 -> #VALUE! | L26: =+L21*L25 -> #VALUE! | M26: =+M21*M25 -> #VALUE! | N26: =+N21*N25 -> #VALUE! | O26: =+O21*O25 -> #VALUE! | P26: =+P21*P25 -> 0
O27: 0
A29: DETERMINACIÓN DEL RESULTADO FISCAL
A30: ( + ) | B30: INVENTARIO ACUMULABLE | C30: 0 | E30: 0 | F30: 0 | G30: 0 | H30: 0 | I30: 0 | J30: 0 | K30: 0 | L30: 0 | M30: 0 | N30: 0 | O30: 0 | P30: =SUM(C30:O30) -> 0
A31: ( - ) | B31: PERDIDAS FISCALES ANTERIORES | C31: 0 | E31: 0 | F31: 0 | G31: =+F3 -> 0 | H31: =+G31 -> 0 | I31: =+H31 -> 0 | J31: =+I31 -> 0 | K31: =+J31 -> 0 | L31: =+K31 -> 0 | M31: =+L31 -> 0 | N31: =+M31 -> 0 | O31: =+N31 -> 0 | P31: 0
A32: ( - ) | B32: PTU PAGADA | C32: 0 | E32: 0 | F32: 0 | G32: 0 | I32: 0 | J32: =+I32 -> 0 | K32: =+J32 -> 0 | L32: =+K32 -> 0 | M32: =+L32 -> 0 | N32: =+M32 -> 0 | O32: =+N32 -> 0 | P32: 0
A33: ( = ) | B33: RESULTADO FISCAL | C33: =+C26+C30-C31-C32 -> 1844785.6 | D33: =D26 -> 1866469.3 | E33: =+E26+E30-E31-E32 -> 2510997.9 | F33: =+F26+F30-F31-F32 -> 15058029 | G33: =+G26+G30-G31-G32 -> #VALUE! | H33: =+H26+H30-H31-H32 -> #VALUE! | I33: =+I26+I30-I31-I32 -> #VALUE! | J33: =+J26+J30-J31-J32 -> #VALUE! | K33: =+K26+K30-K31-K32 -> #VALUE! | L33: =+L26+L30-L31-L32 -> #VALUE! | ... P33: =+P26+P30-P31-P32 -> 0
A36: DETERMINACIÓN DE IMPUESTO
A37: ( * ) | B37: TASA | C37: 0.3 | D37: 0.3 | E37: 0.3 | F37: 0.3 | G37: 0.3 | H37: 0.3 | I37: 0.3 | J37: 0.3 | K37: 0.3 | L37: 0.3 | M37: 30 | N37: 0.3 | O37: 0.3 | P37: 0.3
A38: ( = ) | B38: ISR CAUSADO | C38: =+C33*C37 -> 553435.69 | D38: =+D33*D37 -> 559940.8 | E38: =+E33*E37 -> 753299.37 | F38: =+F33*F37 -> 4517408.8 | G38: =+G33*G37 -> #VALUE! | H38: =+H33*H37 -> #VALUE! | I38: =+I33*I37 -> #VALUE! | J38: =+J33*J37 -> #VALUE! | ... L38: =+L33*L37 -> #VALUE! | M38: =M33*M37% -> #VALUE! | N38: =+N33*N37 -> #VALUE! | O38: =+O33*O37 -> #VALUE! | P38: =+P33*P37 -> 0
A39: ( - ) | B39: PAGOS PROV. EFECTUADOS C/ANTERIORIDAD | C39: 0 | D39: =C38 -> 553435.69 | E39: =+C38 -> 553435.69 | F39: =+E38 -> 753299.37 | G39: =+F39 -> 753299.37 | H39: =+G39 -> 753299.37 | I39: =+H39 -> 753299.37 | J39: =+I39 -> 753299.37 | K39: =+J39 -> 753299.37 | L39: =+K39 -> 753299.37 | M39: =+L39 -> 753299.37 | N39: =+M39 -> 753299.37 | O39: =+N39 -> 753299.37 | P39: 0
A40: ( - ) | B40: RETENCIONES DE ISR BANCARIAS | F40: 1818590
A41: ( = ) | B41: IMPUESTO A CARGO | C41: =+C38-C39-C40 -> 553435.69 | D41: =+D38-D39-D40 -> 6505.108 | E41: =+E38-E39-E40 -> 199863.67 | F41: =+F38-F39-F40 -> 1945519.5 | G41: =+G38-G39-G40 -> #VALUE! | H41: =+H38-H39-H40 -> #VALUE! | I41: =+I38-I39-I40 -> #VALUE! | J41: =+J38-J39-J40 -> #VALUE! | ... P41: =+P38-P39-P40 -> 0
A44: COMPARATIVO vs DECLARACIÓN PRESENTADA
A45: ( vs ) | B45: ISR ENTERADO EN PAGOS PROVISIONALES
A46: ( = ) | B46: DIFERENCIA A CARGO (A FAVOR) | C46: =+C41-C45 -> 553435.69 | E46: =+E41-E45 -> 199863.67 | F46: =+F41-F45 -> 1945519.5 | G46: =+G41-G45 -> #VALUE! | H46: =+H41-H45 -> #VALUE! | I46: =+I41-I45 -> #VALUE! | J46: =+J41-J45 -> #VALUE! | K46: =+K41-K45 -> #VALUE! | L46: =+L41-L45 -> #VALUE! | ... O46: =+O41-O45 -> #VALUE! | P46: =P41-P45 -> 0
A51: DETERMINACIÓN DE IVA
B54: CONCEPTO | C54: ENERO | E54: FEBRERO | F54: MARZO | G54: ABRIL | H54: MAYO | I54: JUNIO | J54: JULIO | K54: AGOSTO | L54: SEPTIEMBRE | M54: OCTUBRE | N54: NOVIEMBRE | O54: DICIEMBRE
B55: IVA ACREDITABLE PAGADO | C55: ='IVA Acreditable'!G251 -> 752187.16 | E55: ='IVA Acreditable'!G443 -> 702016.44 | F55: ='IVA Acreditable'!G661+'IVA 8%'!G5 -> 613498.86
B56: VENTAS COBRADAS 0 Y 16% | C56: ='Aux. ingresos'!AB198 -> 13793677 | E56: ='Aux. ingresos'!AB809 -> 28339739 | F56: ='Aux. ingresos'!AB1006 -> 13578389
B57: TOTAL INGRESOS COBRADOS TASA 0% 16% Y EXENTO | C57: ='Aux. ingresos'!AB199 -> 13879497 | E57: ='Aux. ingresos'!AB808 -> 28623901 | F57: ='Aux. ingresos'!AB1007 -> 13578389
...

Sheet UT. CAMBIARIA
C1: MILLHOUSE MEXICO
C2: MME1507071ZA
A3: Tipo Moneda: MXN | C3: AUXILIAR DE CUENTAS DE 1/03/2025 AL 31/03/2025 | J3: 45765
C4: Cuenta 702-01
A5: Cuenta: | B5: 702-01~Utilidad cambiaria | J5: Saldo Inicial: | K5: 1180070.8
A6: FOLIO | B6: FECHA | C6: TIPO DE POLIZA | D6: DOCUMENTO | E6: TERCERO | F6: CUENTA | G6: DEBE | H6: HABER | I6: SALDO | J6: C. COSTOS | K6: NOTAS
B7: 45722 | C7: Movimiento Conciliado | D7: F4393,F4393,F4394 | E7: CHASE PLASTICS DE MEXICO | F7: 702-01~Utilidad cambiaria | G7: 0 | H7: 2218.63 | I7: 1182289.5
B8: 45723 | C8: Movimiento Conciliado | D8: 12031 | E8: MACH 1 AERO SERVICIOS | F8: 702-01~Utilidad cambiaria | G8: 0 | H8: 48.39 | I8: 1182337.9
B9: 45723 | C9: Movimiento Conciliado | D9: F4001,F3528,F3533,F3524,F3523,F3797,F3526 | E9: HELLA AUTOMOTIVE MEXICO | F9: 702-01~Utilidad cambiaria | G9: 0 | H9: 11182.91 | I9: 1193520.8
B10: 45723 | C10: Movimiento Conciliado | D10: 257527257157 | E10: FAST FORWARD CONSOLIDATORS | F10: 702-01~Utilidad cambiaria | G10: 0 | H10: 108.39 | I10: 1193629.2
B11: 45726 | C11: Movimiento Conciliado | D11: F3604,F3813,F3603,F3785,F3784,F3786 | E11: JABIL EMS SWITZERLAND | F11: 702-01~Utilidad cambiaria | G11: 0 | H11: 12220.87 | I11: 1205850
B12: 45729 | C12: Movimiento Conciliado | D12: 1.0405008e+18 | E12: CBM BANCO, SOCIEDAD ANONIMA, INSTITUCION DE BANCA MULTIPLE, INTEGRANTE DEL GRUPO FINANCIERO CITIBANAMEX | F12: 702-01~Utilidad cambiaria | G12: 0 | H12: 6.89 | I12: 1205856.9
B13: 45729 | C13: Movimiento Conciliado | D13: 1.0405008e+18 | E13: CBM BANCO, SOCIEDAD ANONIMA, INSTITUCION DE BANCA MULTIPLE, INTEGRANTE DEL GRUPO FINANCIERO CITIBANAMEX | F13: 702-01~Utilidad cambiaria | G13: 0 | H13: 1.1 | I13: 1205858
B14: 45730 | C14: Movimiento Conciliado | D14: 8040 | E14: RAGA EXPRESS DE NUEVO LAREDO | F14: 702-01~Utilidad cambiaria | G14: 0 | H14: 1005.59 | I14: 1206863.6
B15: 45730 | C15: Movimiento Conciliado | D15: 284102855 | E15: TRM ESPECIALIZADOS | F15: 702-01~Utilidad cambiaria | G15: 0 | H15: 1532.92 | I15: 1208396.5
B16: 45730 | C16: Movimiento Conciliado | D16: 116114113 | E16: AUTOLINEAS LEGAR | F16: 702-01~Utilidad cambiaria | G16: 0 | H16: 627.09 | I16: 1209023.6
B17: 45730 | C17: Movimiento Conciliado | D17: 254 | E17: COSVERINI | F17: 702-01~Utilidad cambiaria | G17: 0 | H17: 1004.13 | I17: 1210027.8
B18: 45737 | C18: Movimiento Conciliado | D18: 5262 | E18: SPERANTUS | F18: 702-01~Utilidad cambiaria | G18: 0 | H18: 43.86 | I18: 1210071.6
B19: 45737 | C19: Movimiento Conciliado | D19: F3781 | E19: HELLA AUTOMOTIVE MEXICO | F19: 702-01~Utilidad cambiaria | G19: 0 | H19: 66.68 | I19: 1210138.3
B20: 45737 | C20: Movimiento Conciliado | D20: 255 | E20: COSVERINI | F20: 702-01~Utilidad cambiaria | G20: 0 | H20: 584.78 | I20: 1210723.1
B21: 45743 | C21: Movimiento Conciliado | D21: 260 | E21: COSVERINI | F21: 702-01~Utilidad cambiaria | G21: 0 | H21: 595.47 | I21: 1211318.5
B22: 45743 | C22: Movimiento Conciliado | D22: 139132 | E22: AUTOLINEAS LEGAR | F22: 702-01~Utilidad cambiaria | G22: 0 | H22: 499.93 | I22: 1211818.5
B23: 45743 | C23: Movimiento Conciliado | D23: 2985 | E23: TRM ESPECIALIZADOS | F23: 702-01~Utilidad cambiaria | G23: 0 | H23: 386.23 | I23: 1212204.7
B24: 45747 | C24: Movimiento Conciliado | D24: F4427 | E24: BONANZA LOGISTICS | F24: 702-01~Utilidad cambiaria | G24: 0 | H24: 169.5 | I24: 1212374.2
B25: 45747 | C25: Poliza Manual | D25: PM319723-0081 | E25: Fluctuación mes de Marzo (20.4380 - 1 = 19.4380) | F25: 702-01~Utilidad cambiaria | G25: 0 | H25: 262333.41 | I25: 1474707.6 | K25: Fluctuación mes de Marzo (20.4380 - 1 = 19.4380)
F26: 1180070.8 | G26: 0 | H26: 294636.77 | I26: 1474707.6

Sheet ANT. CLIENTES
C1: MILLHOUSE MEXICO
C2: MME1507071ZA
A3: Tipo Moneda: MXN | C3: AUXILIAR DE CUENTAS DE 1/03/2025 AL 31/03/2025 | J3: 45765
C4: Cuenta 206
A5: Cuenta: | B5: 206-01-009~Continental | J5: Saldo Inicial: | K5: 0
A6: FOLIO | B6: FECHA | C6: TIPO DE POLIZA | D6: DOCUMENTO | E6: TERCERO | F6: CUENTA | G6: DEBE | H6: HABER | I6: SALDO | J6: C. COSTOS | K6: NOTAS
B7: 45737 | C7: Movimiento Conciliado | D7: 821600 700405000009772025 | E7: Cobro | F7: 206-01-009~Continental | G7: 0 | H7: 5400 | I7: 5400
B8: 45737 | C8: Movimiento Conciliado | D8: 821599 70040500009762025 | E8: Cobro | F8: 206-01-009~Continental | G8: 0 | H8: 11560 | I8: 16960
H9: =SUM(H7:H8) -> 16960

Sheet PARTE ACTUALIZADA
B3: MONTO PENDIENTE DE PAGAR | C3: INPC ACTUAL | D3: INPC DEL MES EN EL QUE SE DEBIO PAGAR | E3: FACTOR DE ACTUALIZACION | F3: TOTAL DE ACTUALIZACIONES | G3: RECARGOS | H3: TOTAL DE RECARGOS | I3: MONTO A PAGAR
B4: ='Resumen P.P.'!D41 -> 6505.108 | C4: =Hoja1!C5 -> 138.726 | D4: =Hoja1!C4 -> 138.343 | E4: =C4/D4 -> 1.0027685 | F4: =B4*E4 -> 6523.1173 | G4: =Hoja1!I4*2 -> 2.94 | H4: =F4*G4% -> 191.77965 | I4: =F4+H4 -> 6714.897
F5: =F4-B4 -> 18.00927

Sheet Hoja1
B3: Mes | C3: 2025 | D3: 2024 | E3: 2023 | F3: 2022 | G3: 2021 | I3: RECARGO
B4: ENE | C4: 138.343 | D4: 133555 | E4: 1273360 | F4: 1180020 | G4: 1102100 | I4: 1.47
B5: FEB | C5: 138.726 | D5: 133681 | E5: 1280460 | F5: 1189810 | G5: 1109070
B6: MAR | D6: 1340650 | E6: 1283890 | F6: 1201590 | G6: 1118240
B7: ABR | D7: 1343360 | E7: 1283630 | F7: 1208090 | G7: 1121900
B8: MAY | D8: 1340870 | E8: 1280840 | F8: 1210220 | G8: 1124190
B9: JUN | D9: 1345940 | E9: 1282140 | F9: 1220440 | G9: 1130180
B10: JUL | D10: 1360030 | E10: 1288320 | F10: 1229480 | G10: 1136820
B11: AGO | D11: 1360130 | E11: 1295450 | F11: 1238030 | G11: 1138990
B12: SEP | D12: 1360800 | E12: 1301200 | F12: 1245710 | G12: 1146010
B13: OCT | D13: 1368280 | E13: 1306090 | F13: 1252760 | G13: 1155610
B14: NOV | D14: 1374240 | E14: 1314450 | F14: 1259970 | G14: 1168840
B15: DIC | D15: 1379490 | E15: 1323730 | F15: 1264780 | G15: 1173080

Sheet EDR
B1: MILLHOUSE MEXICO
B2: MME1507071ZA
A3: Tipo Moneda: MXN | B3: ESTADO DE RESULTADOS DE 1 DE ENERO DE 2025 AL 28 DE FEBRERO DE 2025
C4: ENERO | D4: FEBRERO | E4: MARZO | F4: ABRIL | G4: MAYO | H4: JUNIO | I4: JULIO | J4: AGOSTO | K4: SEPTIEMBRE | L4: OCTUBRE | M4: NOVIEMBRE | N4: DICIEMBRE | O4: TOTAL | P4: PAGOS PROVISIONAL | Q4: DIFERENCIA | R4: MOTIVO
A5: Ingresos
A6: Ingresos | C6: 25661509 | D6: 8272271.5 | E6: - | F6: - | G6: - | H6: - | I6: - | J6: - | K6: - | L6: - | M6: - | N6: - | O6: 33933781 | P6: ='Resumen P.P.'!P11 -> 43263089 | Q6: =O6-P6 -> -9329308.2
A7: Ventas y/o servicios gravados a la tasa general | C7: 4215287.7 | D7: 1490445.6 | E7: - | F7: - | G7: - | H7: - | I7: - | J7: - | K7: - | L7: - | M7: - | N7: - | O7: 5705733.3
A8: Ventas y/o servicios gravados al 0% | C8: 21336221 | D8: 6688819.8 | E8: - | F8: - | G8: - | H8: - | I8: - | J8: - | K8: - | L8: - | M8: - | N8: - | O8: 28025041
A9: Otros ingresos propios | C9: 110000.25 | D9: 93006.12 | E9: - | F9: - | G9: - | H9: - | I9: - | J9: - | K9: - | L9: - | M9: - | N9: - | O9: 203006.37 | P9: ='Resumen P.P.'!P15 -> 203006.69 | Q9: =O9-P9 -> -0.32
A10: Total | C10: 25661509 | D10: 8272271.5 | E10: - | F10: - | G10: - | H10: - | I10: - | J10: - | K10: - | L10: - | M10: - | N10: - | O10: 33933781
A12: Costos
A13: Devoluciones, descuentos o bonificaciones sobre compras | C13: 277218.22 | D13: 103340.61 | E13: - | F13: - | G13: - | H13: - | I13: - | J13: - | K13: - | L13: - | M13: - | N13: - | O13: 380558.83
A14: Devoluciones, descuentos o bonificaciones sobre compras | C14: 277218.22 | D14: 103340.61 | E14: - | F14: - | G14: - | H14: - | I14: - | J14: - | K14: - | L14: - | M14: - | N14: - | O14: 380558.83
A15: Total | C15: -277218.22 | D15: -103340.61 | E15: - | F15: - | G15: - | H15: - | I15: - | J15: - | K15: - | L15: - | M15: - | N15: - | O15: -380558.83
A17: Gastos
A18: Gastos generales | C18: 56138.61 | D18: 318182.07 | E18: - | F18: - | G18: - | H18: - | I18: - | J18: - | K18: - | L18: - | M18: - | N18: - | O18: 374320.68
A19: Sueldos y salarios | C19: 6.01 | D19: 2.81 | E19: - | F19: - | G19: - | H19: - | I19: - | J19: - | K19: - | L19: - | M19: - | N19: - | O19: 8.82
A20: Indemnizaciones | C20: 27333.6 | D20: 289079.26 | E20: - | F20: - | G20: - | H20: - | I20: - | J20: - | K20: - | L20: - | M20: - | N20: - | O20: 316412.86
A21: Honorarios a personas morales residentes nacionales | C21: 28799 | D21: 29100 | E21: - | F21: - | G21: - | H21: - | I21: - | J21: - | K21: - | L21: - | M21: - | N21: - | O21: 57899
A22: Arrendamiento a personas morales residentes nacionales | C22: 26536.77 | D22: 256600.46 | E22: - | F22: - | G22: - | H22: - | I22: - | J22: - | K22: - | L22: - | M22: - | N22: - | O22: 283137.23
A23: RENTA DE EQUIPO DE TRANSPORTE | C23: - | D23: 1437.87 | E23: - | F23: - | G23: - | H23: - | I23: - | J23: - | K23: - | L23: - | M23: - | N23: - | O23: 1437.87
A24: RENTA DE EQUIPOS | C24: 23174.7 | D24: 23079.62 | E24: - | F24: - | G24: - | H24: - | I24: - | J24: - | K24: - | L24: - | M24: - | N24: - | O24: 46254.32
A25: RENTA LOCAL | C25: 3362.07 | D25: 229910.56 | E25: - | F25: - | G25: - | H25: - | I25: - | J25: - | K25: - | L25: - | M25: - | N25: - | O25: 233272.63
A26: RENTA ESTACIONAMIENTO | C26: - | D26: 2172.41 | E26: - | F26: - | G26: - | H26: - | I26: - | J26: - | K26: - | L26: - | M26: - | N26: - | O26: 2172.41
A27: Gastos generales | C27: 4600245.2 | D27: 3095006.3 | E27: - | F27: - | G27: - | H27: - | I27: - | J27: - | K27: - | L27: - | M27: - | N27: - | O27: 7695251.5
A28: Viáticos y gastos de viaje | C28: 1187.94 | D28: 10793.75 | E28: - | F28: - | G28: - | H28: - | I28: - | J28: - | K28: - | L28: - | M28: - | N28: - | O28: 11981.69
A29: Teléfono, internet | C29: 37317.17 | D29: 25096.27 | E29: - | F29: - | G29: - | H29: - | I29: - | J29: - | K29: - | L29: - | M29: - | N29: - | O29: 62413.44
A30: Limpieza | C30: - | D30: 853.05 | E30: - | F30: - | G30: - | H30: - | I30: - | J30: - | K30: - | L30: - | M30: - | N30: - | O30: 853.05
A31: Seguros y fianzas | C31: - | D31: 10775.42 | E31: - | F31: - | G31: - | H31: - | I31: - | J31: - | K31: - | L31: - | M31: - | N31: - | O31: 10775.42
A32: Cuotas y suscripciones | C32: 274601 | D32: 177922.31 | E32: - | F32: - | G32: - | H32: - | I32: - | J32: - | K32: - | L32: - | M32: - | N32: - | O32: 452523.31
A33: Fletes y acarreos | C33: 4191443.6 | D33: 2766661.5 | E33: - | F33: - | G33: - | H33: - | I33: - | J33: - | K33: - | L33: - | M33: - | N33: - | O33: 6958105.2
A34: Comisiones sobre ventas | C34: 261 | D34: 607 | E34: - | F34: - | G34: - | H34: - | I34: - | J34: - | K34: - | L34: - | M34: - | N34: - | O34: 868
A35: Gastos no deducibles (sin requisitos fiscales) | C35: 95434.43 | D35: 102296.99 | E35: - | F35: - | G35: - | H35: - | I35: - | J35: - | K35: - | L35: - | M35: - | N35: - | O35: 197731.42
A36: Otros gastos generales | C36: 340670.53 | D36: 338425.67 | E36: - | F36: - | G36: - | H36: - | I36: - | J36: - | K36: - | L36: - | M36: - | N36: - | O36: 679096.2
A37: RECOLECCION BASURA | C37: 3100 | D37: 22783.42 | E37: - | F37: - | G37: - | H37: - | I37: - | J37: - | K37: - | L37: - | M37: - | N37: - | O37: 25883.42
A38: SERVICIOS (TEL,AGUA,CFE,CEL ) | C38: 11810.39 | D38: 4056.75 | E38: - | F38: - | G38: - | H38: - | I38: - | J38: - | K38: - | L38: - | M38: - | N38: - | O38: 15867.14
A39: SERVICIO DE LOGISTICA | C39: 321179.8 | D39: 311585.5 | E39: - | F39: - | G39: - | H39: - | I39: - | J39: - | K39: - | L39: - | M39: - | N39: - | O39: 632765.3
A40: CONSUMOS | C40: 4580.34 | D40: - | E40: - | F40: - | G40: - | H40: - | I40: - | J40: - | K40: - | L40: - | M40: - | N40: - | O40: 4580.34
A41: Gastos generales | C41: 12600 | D41: 2356.5 | E41: - | F41: - | G41: - | H41: - | I41: - | J41: - | K41: - | L41: - | M41: - | N41: - | O41: 14956.5
A42: Renta de montacargas | C42: 12600 | D42: - | E42: - | F42: - | G42: - | H42: - | I42: - | J42: - | K42: - | L42: - | M42: - | N42: - | O42: 12600
...

Sheet BAL01
C1: MILLHOUSE MEXICO
C2: MME1507071ZA
A3: Tipo Moneda: MXN | C3: BALANZA DE COMPROBACION DE 1/01/2025 AL 31/01/2025 | E3: MES ENERO 2025 | H3: 45705
A4: No CUENTA | C4: CUENTA | D4: SALDO INICIAL | E4: DEBE | G4: HABER | H4: SALDO FINAL | J4: IMPUESTOS | K4: DIFERENCIA
A5: 102 | B5: D | C5: Bancos | D5: 9859012.4 | E5: 29338688 | G5: 19694593 | H5: 19503108
A6: 102-01 | B6: D | C6: Bancos nacionales | D6: 653554.3 | E6: 10985873 | G6: 8880571.3 | H6: 2758856.3
A7: 102-01-001 | B7: D | C7: BANAMEX CTA 1227167 | D7: 653554.3 | E7: 10985873 | G7: 8880571.3 | H7: 2758856.3
A8: 102-02 | B8: D | C8: Bancos extranjeros | D8: 9205458.1 | E8: 18352815 | G8: 10814022 | H8: 16744251
A9: 102-02-004 | B9: D | C9: BANAMEX DLLS | D9: -24261077 | E9: 1699513.4 | G9: 504157.25 | H9: -23065721
A10: 102-02-005 | B10: D | C10: COMPL BANAMEX DLLS | D10: 33873928 | E10: 16653302 | G10: 10309865 | H10: 40217365
A11: 102-02-010 | B11: D | C11: MONEX USD COMPLEMENTARIA | D11: -407392.5 | E11: 0 | G11: 0 | H11: -407392.5
A12: 105 | B12: D | C12: Clientes | D12: 1.008266e+08 | E12: 26615384 | G12: 14014247 | H12: 1.1342773e+08
A13: 105-01 | B13: D | C13: Clientes nacionales | D13: 1.0086144e+08 | E13: ='BAL2'!G577 -> 122080 | G13: 14014247 | H13: 1.1346257e+08
A14: 105-01-001 | B14: D | C14: Clientes nacionales | D14: 0.01 | E14: 0 | G14: 0 | H14: 0.01
A15: 105-01-005 | B15: D | C15: CLIENTES VARIOS | D15: 56868.55 | E15: 0 | G15: 0 | H15: 56868.55
A16: 105-01-026 | B16: D | C16: EA LOGISTICA SA DE CV DLLS | D16: 0.01 | E16: 0 | G16: 0 | H16: 0.01
A17: 105-01-042 | B17: D | C17: FIT LOGISTICS SA DE CV DLLS | D17: 0.08 | E17: 0 | G17: 0 | H17: 0.08
A18: 105-01-068 | B18: D | C18: CLIENTES VARIOS DLLS | D18: 30603.64 | E18: 0 | G18: 0 | H18: 30603.64
A19: 105-01-070 | B19: D | C19: IE TRADE COMERCIAL S DE RL DE CV DLLS | D19: -41233.53 | E19: 0 | G19: 14165.41 | H19: -55398.94
A20: 105-01-107 | B20: D | C20: GRUPO LOGISTICO MEXICANO DEL NORESTE SA DE CV DLLS | D20: 28308.03 | E20: 0 | G20: 0 | H20: 28308.03
A21: 105-01-109 | B21: D | C21: ELECTRONICA CLARION SA DE CV DLLS | D21: 921902.03 | E21: 0 | G21: 552218.03 | H21: 369684
A22: 105-01-129 | B22: D | C22: EXO TRANSPORT SA DE CV DLLS | D22: 23422.47 | E22: 0 | G22: 0 | H22: 23422.47
A23: 105-01-143 | B23: D | C23: CEVA FREIGHT MANAGEMENT MEXICO SA DE CV | D23: 2065130 | E23: 1123344 | G23: 0 | H23: 3188474
A24: 105-01-147 | B24: D | C24: JABIL CIRCUIT DE CHIHUAHUA S DE RL DE CV | D24: -2498.39 | E24: 0 | G24: 0 | H24: -2498.39
A25: 105-01-148 | B25: D | C25: JABIL CIRCUIT DE MEXICO S DE RL DE CV | D25: 1013571.6 | E25: 0 | G25: 0 | H25: 1013571.6
... A112: 105-02-002 | B112: D | C112: AIRTEMP DE MEXICO SA DE CV | D112: -34839.4 | E112: 0 | G112: 0 | H112: -34839.4
A113: 107 | B113: D | C113: Deudores diversos | D113: -7947570.3 | E113: 52192.9 | G113: 5.27 | H113: -7895382.7
A114: 107-01-001 | B114: D | C114: Milan Expedited Services | D114: 9800 | E114: 0 | G114: 0 | H114: 9800
A115: 107-01-002 | B115: D | C115: KASAI | D115: -420549.84 | E115: 0 | G115: 0 | H115: -420549.84
A116: 107-02 | B116: D | C116: Socios y accionistas | D116: 45000 | E116: 0 | G116: 0 | H116: 45000
A117: 107-05 | B117: D | C117: Otros deudores diversos | D117: -7619699.2 | E117: 52192.9 | G117: 5.27 | H117: -7567511.6
A118: 107-05-004 | B118: D | C118: DEUDORES VARIOS | D118: -5125955 | E118: 0 | G118: 0 | H118: -5125955
A119: 107-05-006 | B119: D | C119: BERNABE SANCHEZ TABOADA | D119: 5000 | E119: 0 | G119: 0 | H119: 5000
A120: 107-05-008 | B120: D | C120: MAURICIO GARCIA ESTRADA | D120: 85959.06 | E120: 0 | G120: 0 | H120: 85959.06
A121: 107-05-010 | B121: D | C121: GASTOS POR COMPROBAR/VIATICOS | D121: 232425.84 | E121: 52192.9 | G121: 0 | H121: 284618.74
A122: 107-05-011 | B122: D | C122: PAGOS PENDIENTES DE FACTURAR O DEVOLVER | D122: 75538.85 | E122: 0 | G122: 0 | H122: 75538.85
A123: 107-05-012 | B123: D | C123: BRUNO TORRES | D123: 20000 | E123: 0 | G123: 0 | H123: 20000
A124: 107-05-013 | B124: D | C124: EXPEDITED INFINITY MY S DE RL DE CV | D124: 136012 | E124: 0 | G124: 0 | H124: 136012
A125: 107-05-014 | B125: D | C125: JORGE CHALITA | D125: 910 | E125: 0 | G125: 0 | H125: 910
... A138: 107-05-025 | B138: D | C138: HUGO ENRIQUE CAVAZOS GUERRA | D138: 37878.76 | E138: 0 | G138: 0 | H138: 37878.76
...

Sheet BAL2
B2: FEBRERO
B3: No CUENTA | C3: NATURALEZA | D3: CUENTA | E3: SALDO INICIAL | F3: DEBE | G3: HABER | H3: SALDO FINAL
B4: 102 | C4: D | D4: Bancos | E4: 24841449 | F4: 34861573 | G4: 16571990 | H4: 43131032
B5: 102-01 | C5: D | D5: Bancos nacionales | E5: 4014261.7 | F5: 9637400.6 | G5: 9799826.6 | H5: 3851835.7
B6: 102-01-001 | C6: D | D6: BANAMEX CTA 1227167 | E6: 4014261.7 | F6: 9637400.6 | G6: 9799826.6 | H6: 3851835.7
B7: 102-02 | C7: D | D7: Bancos extranjeros | E7: 20827188 | F7: 25224172 | G7: 6772163.5 | H7: 39279196
B8: 102-02-004 | C8: D | D8: BANAMEX DLLS | E8: -22894884 | F8: 3254717.4 | G8: 315392.16 | H8: -19955559
B9: 102-02-005 | C9: D | D9: COMPL BANAMEX DLLS | E9: 44070665 | F9: 21969455 | G9: 6456771.4 | H9: 59583348
B10: 102-02-009 | C10: D | D10: MONEX USD | E10: 3000 | F10: 0 | G10: 0 | H10: 3000
B11: 102-02-010 | C11: D | D11: MONEX USD COMPLEMENTARIA | E11: -351593.1 | F11: 0 | G11: 0 | H11: -351593.1
B12: 105 | C12: D | D12: Clientes | E12: 1.3181517e+08 | F12: 8417736.7 | G12: 28542335 | H12: 1.1169057e+08
B13: 105-01 | C13: D | D13: Clientes nacionales | E13: 1.3185001e+08 | F13: 8417736.7 | G13: 28542335 | H13: 1.1172541e+08
B14: 105-01-001 | C14: D | D14: Clientes nacionales | E14: 0.01 | F14: 0 | G14: 0 | H14: 0.01
B15: 105-01-004 | C15: D | D15: NORGISTICS MEXICO SA DE CV | E15: 15755.7 | F15: 0 | G15: 0 | H15: 15755.7
... B785: 899-04 | C785: D | D785: Traspaso Bancario | E785: 0 | F785: 5557500 | G785: 5557500 | H785: 0
B786: TOTALES | F786: 70061335 | G786: 70061335

Sheet BAL3
B2: MARZO
B3: No CUENTA | C3: NATURALEZA | D3: CUENTA | E3: SALDO INICIAL | F3: DEBE | G3: HABER | H3: SALDO FINAL
B4: 102 | C4: D | D4: Bancos | E4: 43131032 | F4: 21474140 | G4: 17991513 | H4: 46613659
B5: 102-01 | C5: D | D5: Bancos nacionales | E5: 3851835.7 | F5: 8530709 | G5: 9809518.3 | H5: 2573026.4
B6: 102-01-001 | C6: D | D6: BANAMEX CTA 1227167 | E6: 3851835.7 | F6: 8530709 | G6: 9809518.3 | H6: 2573026.4
B7: 102-02 | C7: D | D7: Bancos extranjeros | E7: 39279196 | F7: 12943431 | G7: 8181994.9 | H7: 44040633
B8: 102-02-004 | C8: D | D8: BANAMEX DLLS | E8: -19955559 | F8: 627362.31 | G8: 407329.02 | H8: -19735526
B9: 102-02-005 | C9: D | D9: COMPL BANAMEX DLLS | E9: 59583348 | F9: 12316069 | G9: 7774665.9 | H9: 64124752
B10: 102-02-009 | C10: D | D10: MONEX USD | E10: 3000 | F10: 0 | G10: 0 | H10: 3000
B11: 102-02-010 | C11: D | D11: MONEX USD COMPLEMENTARIA | E11: -351593.1 | F11: 0 | G11: 0 | H11: -351593.1
B12: 105 | C12: D | D12: Clientes | E12: 1.1169057e+08 | F12: 9702176 | G12: 13789928 | H12: 1.0760282e+08
B13: 105-01 | C13: D | D13: Clientes nacionales | E13: 1.1172541e+08 | F13: 9702176 | G13: 13789928 | H13: 1.0763766e+08
B14: 105-01-001 | C14: D | D14: Clientes nacionales | E14: 0.01 | F14: 0 | G14: 0 | H14: 0.01
B15: 105-01-004 | C15: D | D15: NORGISTICS MEXICO SA DE CV | E15: 15755.7 | F15: 0 | G15: 0 | H15: 15755.7
... B166: 113 | C166: D | D166: Impuestos a favor | E166: 42278678 | F166: 398077.25 | G166: 223.78 | H166: 42676531
B167: 113-01 | C167: D | D167: IVA a favor | E167: 5997042 | F167: 396693.85 | G167: 0 | H167: 6393735.8 | I167: ='Resumen P.P.'!F64-'Resumen P.P.'!F63 -> 396693.86 | J167: =F167-I167 -> -0.0055064916
B168: 113-02 | C168: D | D168: ISR a favor | E168: 36026668 | F168: 0 | G168: 0 | H168: 36026668
B169: 113-06 | C169: D | D169: Subsidio al empleo | E169: 326.27 | F169: 0 | G169: 0 | H169: 326.27
B170: 113-08 | C170: D | D170: Otros impuestos a favor | E170: 254641.35 | F170: 1705.05 | G170: 223.78 | H170: 256122.62
B171: 114 | C171: D | D171: Pagos provisionales | E171: 7233513 | F171: 0 | G171: 0 | H171: 7233513
B172: 114-01 | C172: D | D172: Pagos provisionales de ISR | E172: 7233513 | F172: 0 | G172: 0 | H172: 7233513
B173: 118 | C173: D | D173: Impuestos acreditables pagados | E173: 6973886 | F173: 613498.86 | G173: 613498.86 | H173: 6973886
B174: 118-01 | C174: D | D174: IVA acreditable pagado | E174: 6972918 | F174: 613498.86 | G174: 613498.86 | H174: 6972918
B175: 118-01-001 | C175: D | D175: IVA TASA 16% | E175: 6969762.9 | F175: 612667.5 | G175: 612667.5 | H175: 6969762.9 | I175: ='Aux. egresos'!AH1001 -> 612667.5 | J175: =G175-I175 -> -0.00079149159
B176: 118-01-002 | C176: D | D176: IVA TASA 8% FRONTERA | E176: 3155.08 | F176: 831.36 | G176: 831.36 | H176: 3155.08 | I176: ='Aux. egresos'!AI1001 -> 831.35787 | J176: =G176-I176 -> 0.002132
B177: 118-03 | C177: D | D177: IEPS acreditable pagado | E177: 967.97 | F177: 0 | G177: 0 | H177: 967.97
B178: 119 | C178: D | D178: Impuestos acreditables por pagar | E178: 2628981.5 | F178: 601222.7 | G178: 613797.14 | H178: 2616407.1
B179: 119-01 | C179: D | D179: IVA pendiente de pago | E179: 2629039.1 | F179: 601219.29 | G179: 613797.14 | H179: 2616461.3
B180: 119-03 | C180: D | D180: IEPS pendiente de pago | E180: -57.58 | F180: 3.41 | G180: 0 | H180: -54.17
B181: 120 | C181: D | D181: Anticipo a proveedores | E181: 552020.89 | F181: 0 | G181: 0 | H181: 552020.89
B182: 120-01 | C182: D | D182: Anticipo a proveedores nacional | E182: 531941.46 | F182: 0 | G182: 0 | H182: 531941.46
B183: 120-01-001 | C183: D | D183: JIMSA TRANSPORTES | E183: 2000 | F183: 0 | G183: 0 | H183: 2000
B184: 120-02 | C184: D | D184: Anticipo a proveedores extranjero | E184: 18079.43 | F184: 0 | G184: 0 | H184: 18079.43
B185: 155 | C185: D | D185: Mobiliario y equipo de oficina | E185: 1586114.8 | F185: 0 | G185: 0 | H185: 1586114.8
B186: 155-01 | C186: D | D186: Mobiliario y equipo de oficina | E186: 1586114.8 | F186: 0 | G186: 0 | H186: 1586114.8
B187: 155-01-001 | C187: D | D187: INVERSION 2016 | E187: 164364.42 | F187: 0 | G187: 0 | H187: 164364.42
B188: 155-01-002 | C188: D | D188: INVERSION 2017 | E188: 4482.76 | F188: 0 | G188: 0 | H188: 4482.76
... B662: 208 | C662: A | D662: Impuestos trasladados cobrados | E662: 2836274.4 | F662: 217126.66 | G662: 216805.01 | H662: 2835952.7
B663: 208-01 | C663: A | D663: IVA trasladado cobrado | E663: 2836274.4 | F663: 216805.01 | G663: 216805.01 | H663: 2836274.3 | I663: ='Aux. ingresos'!AH1005 -> 216805 | J663: =F663-I663 -> 0.006847
B664: 209 | C664: A | D664: Impuestos trasladados no cobrados | E664: 3061310.8 | F664: 215282.33 | G664: 163726.94 | H664: 3009755.4
...

Sheet FACTURAS INGRESOS
B2: ENERO
B3: SUCURSAL | C3: AGENTE | D3: T. VENTA | E3: COD. CLIENTE | F3: CLIENTE | G3: COMPROBANTE | H3: FOLIO | I3: UUID | J3: F. EXP. | K3: ESTATUS | L3: METODO PAGO | M3: FORMA PAGO | N3: PLAZO | O3: VENCIMIENTO | P3: SUBTOTAL | Q3: DESCUENTO | R3: % | S3: T. IMPUESTOS | T3: TOTAL | U3: PAGADO | V3: MONEDA | W3: CONTABILIZADA | X3: IVA Tasa 0 | Y3: IVA Tasa 16.00 | Z3: IVA Tasa 0.000000
B4: ND | C4: ND | D4: ND | E4: MILLHOUSE LOGISTICS I.N.C. | F4: MILLHOUSE LOGISTICS I.N.C. | G4: INGRESO | H4: F4137 | I4: BB12FD56-C3FA-43F8-AEB1-F281FEFFDAAD | J4: 2025-01-06 | K4: Vigente | L4: PPD | M4: 99 Por definir | N4: CREDITO: | O4: 2025-01-06 | P4: 3103755 | Q4: 0 | R4: 0 | S4: 0 | T4: 3103755 | U4: 150000 | V4: USD | W4: SI | X4: 0 | Y4: 0 | Z4: 0
B5: ND | C5: ND | D5: ND | E5: BONANZA LOGISTICS | F5: BONANZA LOGISTICS | G5: INGRESO | H5: F4138 | I5: E595447A-7DA6-4613-BE3C-041FAC1C8027 | J5: 2025-01-06 | K5: Vigente | L5: PPD | M5: 99 Por definir | N5: CREDITO: | O5: 2025-01-06 | P5: 31037.55 | Q5: 0 | R5: 0 | S5: 0 | T5: 31037.55 | U5: 0 | V5: USD | W5: SI | X5: 0 | Y5: 0 | Z5: 0
B6: ND | C6: ND | D6: ND | E6: CEVA FREIGHT MANAGEMENT MEXICO | F6: CEVA FREIGHT MANAGEMENT MEXICO | G6: INGRESO | H6: F4139 | I6: 69BB96BF-BF61-4B3C-A69B-CA0DCF8E74C1 | J6: 2025-01-06 | K6: Vigente | L6: PPD | M6: 99 Por definir | N6: CREDITO: | O6: 2025-01-06 | P6: 53800 | Q6: 0 | R6: 0 | S6: 8608 | T6: 62408 | U6: 0 | V6: MXN | W6: SI | X6: 0 | Y6: 8608 | Z6: 0
B7: ND | C7: ND | D7: ND | E7: CEVA FREIGHT MANAGEMENT MEXICO | F7: CEVA FREIGHT MANAGEMENT MEXICO | G7: INGRESO | H7: F4140 | I7: 8269E833-7CFF-4F7D-B280-B858BA05FF90 | J7: 2025-01-06 | K7: Vigente | L7: PPD | M7: 99 Por definir | N7: CREDITO: | O7: 2025-01-06 | P7: 53800 | Q7: 0 | R7: 0 | S7: 8608 | T7: 62408 | U7: 0 | V7: MXN | W7: SI | X7: 0 | Y7: 8608 | Z7: 0
B8: ND | C8: ND | D8: ND | E8: CEVA FREIGHT MANAGEMENT MEXICO | F8: CEVA FREIGHT MANAGEMENT MEXICO | G8: INGRESO | H8: F4141 | I8: 1D173DF4-0AF8-45CF-96FF-57DC9EA6332F | J8: 2025-01-06 | K8: Vigente | L8: PPD | M8: 99 Por definir | N8: CREDITO: | O8: 2025-01-06 | P8: 53800 | Q8: 0 | R8: 0 | S8: 8608 | T8: 62408 | U8: 0 | V8: MXN | W8: SI | X8: 0 | Y8: 8608 | Z8: 0
B9: ND | C9: ND | D9: ND | E9: CHASE PLASTICS DE MEXICO | F9: CHASE PLASTICS DE MEXICO | G9: INGRESO | H9: F4142 | I9: B0824F95-A398-4BA0-A8CD-02140CDC8205 | J9: 2025-01-06 | K9: Vigente | L9: PPD | M9: 99 Por definir | N9: CREDITO: | O9: 2025-01-06 | P9: 9000 | Q9: 0 | R9: 0 | S9: 1440 | T9: 10440 | U9: 0 | V9: MXN | W9: SI | X9: 0 | Y9: 1440 | Z9: 0
B10: ND | C10: ND | D10: ND | E10: CHASE PLASTICS DE MEXICO | F10: CHASE PLASTICS DE MEXICO | G10: INGRESO | H10: F4143 | I10: 9498F893-C0D9-4FC6-A3CF-E944F880BABF | J10: 2025-01-06 | K10: Vigente | L10: PPD | M10: 99 Por definir | N10: CREDITO: | O10: 2025-01-06 | P10: 5000 | Q10: 0 | R10: 0 | S10: 800 | T10: 5800 | U10: 0 | V10: MXN | W10: SI | X10: 0 | Y10: 800 | Z10: 0
B11: ND | C11: ND | D11: ND | E11: DSV ROAD | F11: DSV ROAD | G11: INGRESO | H11: F4144 | I11: F3E7654E-A246-4E56-8E30-252B5EAB1A0E | J11: 2025-01-06 | K11: Vigente | L11: PPD | M11: 99 Por definir | N11: CREDITO: | O11: 2025-01-06 | P11: 70351.78 | Q11: 0 | R11: 0 | S11: 0 | T11: 70351.78 | U11: 0 | V11: USD | W11: SI | X11: 0 | Y11: 0 | Z11: 0
B12: ND | C12: ND | D12: ND | E12: DSV ROAD | F12: DSV ROAD | G12: INGRESO | H12: F4145 | I12: 67456DB2-C78D-48D4-8539-16BCBD26D588 | J12: 2025-01-06 | K12: Vigente | L12: PPD | M12: 99 Por definir | N12: CREDITO: | O12: 2025-01-06 | P12: 95595.65 | Q12: 0 | R12: 0 | S12: 0 | T12: 95595.65 | U12: 0 | V12: USD | W12: SI | X12: 0 | Y12: 0 | Z12: 0
B13: ND | C13: ND | D13: ND | E13: HELLA AUTOMOTIVE MEXICO | F13: HELLA AUTOMOTIVE MEXICO | G13: INGRESO | H13: F4146 | I13: D2846251-2683-494C-B1DC-1DA6617A1A3F | J13: 2025-01-06 | K13: Vigente | L13: PPD | M13: 99 Por definir | N13: CREDITO: | O13: 2025-01-06 | P13: 134496.05 | Q13: 0 | R13: 0 | S13: 0 | T13: 134496.05 | U13: 0 | V13: USD | W13: SI | X13: 0 | Y13: 0 | Z13: 0
B14: ND | C14: ND | D14: ND | E14: HELLA AUTOMOTIVE MEXICO | F14: HELLA AUTOMOTIVE MEXICO | G14: INGRESO | H14: F4147 | I14: 65F6910A-2D12-4DAE-A583-261C65A6482F | J14: 2025-01-06 | K14: Vigente | L14: PPD | M14: 99 Por definir | N14: CREDITO: | O14: 2025-01-06 | P14: 67454.94 | Q14: 0 | R14: 0 | S14: 0 | T14: 67454.94 | U14: 0 | V14: USD | W14: SI | X14: 0 | Y14: 0 | Z14: 0
B15: ND | C15: ND | D15: ND | E15: HELLA AUTOMOTIVE MEXICO | F15: HELLA AUTOMOTIVE MEXICO | G15: INGRESO | H15: F4148 | I15: A7FE29A4-9119-4A9B-B83F-FBB3173228A0 | J15: 2025-01-06 | K15: Vigente | L15: PPD | M15: 99 Por definir | N15: CREDITO: | O15: 2025-01-06 | P15: 64144.27 | Q15: 0 | R15: 0 | S15: 0 | T15: 64144.27 | U15: 0 | V15: USD | W15: SI | X15: 0 | Y15: 0 | Z15: 0
... B21: ND | C21: ND | D21: ND | E21: CLUB TURAVIA | F21: CLUB TURAVIA | G21: INGRESO | H21: F4155 | I21: 48CF9772-11E3-47E3-84A3-B383203A495D | J21: 2025-01-06 | K21: Vigente | L21: PPD | M21: 99 Por definir | N21: CREDITO: | O21: 2025-01-06 | P21: 3488.32 | Q21: 0 | R21: 0 | S21: 558.13 | T21: 4046.45 | U21: 4046.45 | V21: MXN | W21: SI | X21: 0 | Y21: 558.13 | Z21: 0
B22: ND | C22: ND | D22: ND | F22: KASAI MEXICANA | G22: INGRESO | H22: F4156 | I22: A95465C9-BF24-4A7B-97FF-58EE558C9F40 | J22: 2025-01-06 | K22: Vigente | L22: PPD | M22: 99 Por definir | N22: CREDITO: | O22: 2025-01-06 | P22: 97044.07 | Q22: 0 | R22: 0 | S22: 0 | T22: 97044.07 | U22: 0 | V22: USD | W22: SI | X22: 0 | Y22: 0 | Z22: 0
B23: ND | C23: ND | D23: ND | E23: KASAI MEXICANA | F23: KASAI MEXICANA | G23: INGRESO | H23: F4157 | I23: 2971DD0A-7CFD-4F08-96B9-E73348519FC2 | J23: 2025-01-06 | K23: Vigente | L23: PPD | M23: 99 Por definir | N23: CREDITO: | O23: 2025-01-06 | P23: 144014.23 | Q23: 0 | R23: 0 | S23: 0 | T23: 144014.23 | U23: 0 | V23: USD | W23: SI | X23: 0 | Y23: 0 | Z23: 0
B24: ND | C24: ND | D24: ND | F24: KASAI MEXICANA | G24: INGRESO | H24: F4158 | I24: 3D99EAE3-A43D-4194-8EFC-F799EA0EE985 | J24: 2025-01-06 | K24: Vigente | L24: PPD | M24: 99 Por definir | N24: CREDITO: | O24: 2025-01-06 | P24: 84836 | Q24: 0 | R24: 0 | S24: 13573.76 | T24: 98409.76 | U24: 0 | V24: MXN | W24: SI | X24: 0 | Y24: 13573.76 | Z24: 0
B25: ND | C25: ND | D25: ND | F25: KASAI MEXICANA | G25: INGRESO | H25: F4159 | I25: 7C40825D-3A7A-4AB9-BB0D-8538EAEF00FD | J25: 2025-01-06 | K25: Vigente | L25: PPD | M25: 99 Por definir | N25: CREDITO: | O25: 2025-01-06 | P25: 38500 | Q25: 0 | R25: 0 | S25: 6160 | T25: 44660 | U25: 0 | V25: MXN | W25: SI | X25: 0 | Y25: 6160 | Z25: 0
B26: ND | C26: ND | D26: ND | F26: KASAI MEXICANA | G26: INGRESO | H26: F4160 | I26: D9E85B46-95C3-46B5-AD74-0823C70CF6A8 | J26: 2025-01-06 | K26: Vigente | L26: PPD | M26: 99 Por definir | N26: CREDITO: | O26: 2025-01-06 | P26: 80000 | Q26: 0 | R26: 0 | S26: 12800 | T26: 92800 | U26: 0 | V26: MXN | W26: SI | X26: 0 | Y26: 12800 | Z26: 0
B27: ND | C27: ND | D27: ND | E27: MDE TRUCKING | F27: MDE TRUCKING | G27: INGRESO | H27: F4161 | I27: 9EC866F2-D799-4124-9ADC-4BB62482739F | J27: 2025-01-06 | K27: Vigente | L27: PPD | M27: 99 Por definir | N27: CREDITO: | O27: 2025-01-06 | P27: 95181.82 | Q27: 0 | R27: 0 | S27: 0 | T27: 95181.82 | U27: 0 | V27: USD | W27: SI | X27: 0 | Y27: 0 | Z27: 0
B28: ND | C28: ND | D28: ND | E28: MOLEX DE MEXICO GUADALAJARA 2 | F28: MOLEX DE MEXICO GUADALAJARA 2 | G28: INGRESO | H28: F4162 | I28: DC2B4351-B9E7-425B-8BE0-26FB6AE415D4 | J28: 2025-01-06 | K28: Vigente | L28: PPD | M28: 99 Por definir | N28: CREDITO: | O28: 2025-01-06 | P28: 18500 | Q28: 0 | R28: 0 | S28: 2960 | T28: 21460 | U28: 0 | V28: MXN | W28: SI | X28: 0 | Y28: 2960 | Z28: 0
B29: ND | C29: ND | D29: ND | E29: MOLEX DE MEXICO GUADALAJARA 2 | F29: MOLEX DE MEXICO GUADALAJARA 2 | G29: INGRESO | H29: F4163 | I29: D06CACF7-A2FD-41EE-A4CC-9BFAAFBCD206 | J29: 2025-01-06 | K29: Vigente | L29: PPD | M29: 99 Por definir | N29: CREDITO: | O29: 2025-01-06 | P29: 3000 | Q29: 0 | R29: 0 | S29: 480 | T29: 3480 | U29: 0 | V29: MXN | W29: SI | X29: 0 | Y29: 480 | Z29: 0
B30: ND | C30: ND | D30: ND | E30: MOLEX DE MEXICO GUADALAJARA 2 | F30: MOLEX DE MEXICO GUADALAJARA 2 | G30: INGRESO | H30: F4164 | I30: 852800C1-75DF-40E2-861B-B36F65E18099 | J30: 2025-01-06 | K30: Vigente | L30: PPD | M30: 99 Por definir | N30: CREDITO: | O30: 2025-01-06 | P30: 2200 | Q30: 0 | R30: 0 | S30: 352 | T30: 2552 | U30: 0 | V30: MXN | W30: SI | X30: 0 | Y30: 352 | Z30: 0
B31: ND | C31: ND | D31: ND | E31: MOLEX DE MEXICO GUADALAJARA 2 | F31: MOLEX DE MEXICO GUADALAJARA 2 | G31: INGRESO | H31: F4165 | I31: 8E4CDAB7-B4F2-46B7-BC73-FFDC5AEA8AC0 | J31: 2025-01-06 | K31: Vigente | L31: PPD | M31: 99 Por definir | N31: CREDITO: | O31: 2025-01-06 | P31: 25000 | Q31: 0 | R31: 0 | S31: 4000 | T31: 29000 | U31: 0 | V31: MXN | W31: SI | X31: 0 | Y31: 4000 | Z31: 0
B32: ND | C32: ND | D32: ND | E32: PCE PARAGON SOLUTIONS (MEXICO) | F32: PCE PARAGON SOLUTIONS (MEXICO) | G32: INGRESO | H32: F4166 | I32: 94F1DE06-C5B1-49A5-B980-CB63B3DB2097 | J32: 2025-01-06 | K32: Vigente | L32: PPD | M32: 99 Por definir | N32: CREDITO: | O32: 2025-01-06 | P32: 78525 | Q32: 0 | R32: 0 | S32: 0 | T32: 78525 | U32: 0 | V32: USD | W32: SI | X32: 0 | Y32: 0 | Z32: 0
B33: ND | C33: ND | D33: ND | E33: PCE PARAGON SOLUTIONS (MEXICO) | F33: PCE PARAGON SOLUTIONS (MEXICO) | G33: INGRESO | H33: F4167 | I33: 7B5C2AA3-0A9C-4F7E-9852-F77F40A72506 | J33: 2025-01-06 | K33: Vigente | L33: PPD | M33: 99 Por definir | N33: CREDITO: | O33: 2025-01-06 | P33: 78525 | Q33: 0 | R33: 0 | S33: 0 | T33: 78525 | U33: 0 | V33: USD | W33: SI | X33: 0 | Y33: 0 | Z33: 0
B34: ND | C34: ND | D34: ND | E34: PCE PARAGON SOLUTIONS (MEXICO) | F34: PCE PARAGON SOLUTIONS (MEXICO) | G34: INGRESO | H34: F4168 | I34: 79FC58C9-5F0E-4377-8975-BA8D799B3763 | J34: 2025-01-06 | K34: Vigente | L34: PPD | M34: 99 Por definir | N34: CREDITO: | O34: 2025-01-06 | P34: 78525 | Q34: 0 | R34: 0 | S34: 0 | T34: 78525 | U34: 0 | V34: USD | W34: SI | X34: 0 | Y34: 0 | Z34: 0
B35: ND | C35: ND | D35: ND | E35: PCE PARAGON SOLUTIONS (MEXICO) | F35: PCE PARAGON SOLUTIONS (MEXICO) | G35: INGRESO | H35: F4169 | I35: 82E0B2C3-DDE1-44DB-87F6-F57D761B14A5 | J35: 2025-01-06 | K35: Vigente | L35: PPD | M35: 99 Por definir | N35: CREDITO: | O35: 2025-01-06 | P35: 78525 | Q35: 0 | R35: 0 | S35: 0 | T35: 78525 | U35: 0 | V35: USD | W35: SI | X35: 0 | Y35: 0 | Z35: 0
B36: ND | C36: ND | D36: ND | E36: PCE PARAGON SOLUTIONS (MEXICO) | F36: PCE PARAGON SOLUTIONS (MEXICO) | G36: INGRESO | H36: F4170 | I36: C4CCEF46-A4E2-4149-8893-03DA186D0576 | J36: 2025-01-06 | K36: Vigente | L36: PPD | M36: 99 Por definir | N36: CREDITO: | O36: 2025-01-06 | P36: 78525 | Q36: 0 | R36: 0 | S36: 0 | T36: 78525 | U36: 0 | V36: USD | W36: SI | X36: 0 | Y36: 0 | Z36: 0
B37: ND | C37: ND | D37: ND | E37: PCE PARAGON SOLUTIONS (MEXICO) | F37: PCE PARAGON SOLUTIONS (MEXICO) | G37: INGRESO | H37: F4171 | I37: F84E79CF-95D1-437F-AD67-021B3AAF27F4 | J37: 2025-01-06 | K37: Vigente | L37: PPD | M37: 99 Por definir | N37: CREDITO: | O37: 2025-01-06 | P37: 78525 | Q37: 0 | R37: 0 | S37: 0 | T37: 78525 | U37: 0 | V37: USD | W37: SI | X37: 0 | Y37: 0 | Z37: 0
B38: ND | C38: ND | D38: ND | E38: PCE PARAGON SOLUTIONS (MEXICO) | F38: PCE PARAGON SOLUTIONS (MEXICO) | G38: INGRESO | H38: F4172 | I38: C1575204-335D-42C7-B329-0B298C5B392E | J38: 2025-01-06 | K38: Vigente | L38: PPD | M38: 99 Por definir | N38: CREDITO: | O38: 2025-01-06 | P38: 78525 | Q38: 0 | R38: 0 | S38: 0 | T38: 78525 | U38: 0 | V38: USD | W38: SI | X38: 0 | Y38: 0 | Z38: 0
B39: ND | C39: ND | D39: ND | E39: SEA CARGO LOGISTICS | F39: SEA CARGO LOGISTICS | G39: INGRESO | H39: F4173 | I39: 8DD3F855-232A-4D2C-BD59-061C5B547BC2 | J39: 2025-01-06 | K39: Vigente | L39: PPD | M39: 99 Por definir | N39: CREDITO: | O39: 2025-01-06 | P39: 11794.27 | Q39: 0 | R39: 0 | S39: 0 | T39: 11794.27 | U39: 570 | V39: USD | W39: SI | X39: 0 | Y39: 0 | Z39: 0
B40: ND | C40: ND | D40: ND | F40: SEA CARGO LOGISTICS | G40: INGRESO | H40: F4174 | I40: 57595518-C9BE-4C23-BBC0-6A985DFA2D17 | J40: 2025-01-06 | K40: Vigente | L40: PPD | M40: 99 Por definir | N40: CREDITO: | O40: 2025-01-06 | P40: 127253.96 | Q40: 0 | R40: 0 | S40: 0 | T40: 127253.96 | U40: 6150 | V40: USD | W40: SI | X40: 0 | Y40: 0 | Z40: 0
B41: ND | C41: ND | D41: ND | E41: SEA CARGO LOGISTICS | F41: SEA CARGO LOGISTICS | G41: INGRESO | H41: F4175 | I41: 2313AD56-2873-4162-ACDE-19B5FA31EA83 | J41: 2025-01-06 | K41: Vigente | L41: PPD | M41: 99 Por definir | N41: CREDITO: | O41: 2025-01-06 | P41: 194501.98 | Q41: 0 | R41: 0 | S41: 0 | T41: 194501.98 | U41: 0 | V41: USD | W41: SI | X41: 0 | Y41: 0 | Z41: 0
B42: ND | C42: ND | D42: ND | E42: SEA CARGO LOGISTICS | F42: SEA CARGO LOGISTICS | G42: INGRESO | H42: F4176 | I42: C0D0C4A0-AA0E-43A4-95F3-F3ACA9E1A793 | J42: 2025-01-06 | K42: Vigente | L42: PPD | M42: 99 Por definir | N42: CREDITO: | O42: 2025-01-06 | P42: 127253.96 | Q42: 0 | R42: 0 | S42: 0 | T42: 127253.96 | U42: 6150 | V42: USD | W42: SI | X42: 0 | Y42: 0 | Z42: 0
B43: ND | C43: ND | D43: ND | E43: SEA CARGO LOGISTICS | F43: SEA CARGO LOGISTICS | G43: INGRESO | H43: F4177 | I43: D01002B3-7BF2-44F5-A1F4-44D4A6ADDBD2 | J43: 2025-01-06 | K43: Vigente | L43: PPD | M43: 99 Por definir | N43: CREDITO: | O43: 2025-01-06 | P43: 127253.96 | Q43: 0 | R43: 0 | S43: 0 | T43: 127253.96 | U43: 0 | V43: USD | W43: SI | X43: 0 | Y43: 0 | Z43: 0
B44: ND | C44: ND | D44: ND | E44: SEA CARGO LOGISTICS | F44: SEA CARGO LOGISTICS | G44: INGRESO | H44: F4178 | I44: 5712BFD0-CE53-4C11-8395-9869A04D2530 | J44: 2025-01-06 | K44: Vigente | L44: PPD | M44: 99 Por definir | N44: CREDITO: | O44: 2025-01-06 | P44: 127253.96 | Q44: 0 | R44: 0 | S44: 0 | T44: 127253.96 | U44: 0 | V44: USD | W44: SI | X44: 0 | Y44: 0 | Z44: 0
B45: ND | C45: ND | D45: ND | E45: UNIVERSAL SCIENTIFIC INDUSTRIAL DE MEXICO | F45: UNIVERSAL SCIENTIFIC INDUSTRIAL DE MEXICO | G45: INGRESO | H45: F4179 | I45: 643B7E7F-5731-440F-BAAC-086BB766E1BE | J45: 2025-01-06 | K45: Vigente | L45: PPD | M45: 99 Por definir | N45: CREDITO: | O45: 2025-01-06 | P45: 129323.13 | Q45: 0 | R45: 0 | S45: 0 | T45: 129323.13 | U45: 0 | V45: USD | W45: SI | X45: 0 | Y45: 0 | Z45: 0
B46: ND | C46: ND | D46: ND | E46: CEVA FREIGHT MANAGEMENT MEXICO | F46: CEVA FREIGHT MANAGEMENT MEXICO | G46: INGRESO | H46: F4180 | I46: D73B390F-9290-480C-81BB-28DB64E05D9D | J46: 2025-01-06 | K46: Vigente | L46: PPD | M46: 99 Por definir | N46: CREDITO: | O46: 2025-01-06 | P46: 53800 | Q46: 0 | R46: 0 | S46: 8608 | T46: 62408 | U46: 0 | V46: MXN | W46: SI | X46: 0 | Y46: 8608 | Z46: 0
...

Sheet ING.MIADMIN
A1: Verificado o Asoc | B1: Estado SAT | C1: CfdiRelacionados | D1: UUID | E1: Serie | F1: Folio | G1: Version | H1: TipoComprobante | I1: FechaTimbradoXML | J1: FechaEmisionXML | K1: LugarDeExpedicion | L1: RFC Emisor | M1: Nombre Emisor | N1: RegimenFiscal | O1: RFC Receptor | P1: Nombre Receptor | Q1: UsoCFDI | R1: RegimenFiscalReceptor | S1: DomicilioFiscalReceptor | T1: FormaDePago | U1: Metodo de Pago | V1: Complementos comprobante | W1: Conceptos | X1: Complementos conceptos | Y1: SubTotal | Z1: Descuento | AA1: Total Trasladados | AB1: Total Retenidos | AC1: Total | AG1: Moneda | AH1: TipoCambio | AI1: IVA Exento | AJ1: IVA Exento Base | AK1: IVA Cero Base | AL1: IVA 8 Importe | AM1: IVA 16 Importe | AN1: ISR Retenido | AO1: IVA Retenido | AP1: IEPS Retenido | AQ1: Ret ISR 1.25 Importe | AR1: Ret IVA 10.6667 Importe | AS1: Ret IVA 8 Importe | AT1: Ret IVA 6 Importe | AU1: Ret IVA 16 Importe | AV1: No Certificado SAT | AW1: No Certificado Emisor | AX1: Archivo XML
D2: 05BF2ED7-0CE4-42C0-B1D6-D2CDCEE44E75 | E2: F | F2: F4473 | G2: 4 | H2: I - Ingreso | I2: 2025-03-04T10:37:38 | J2: 2025-03-04T10:35:39 | K2: 66260 | L2: MME1507071ZA | M2: MILLHOUSE MEXICO | N2: 601 - General de Ley Personas Morales | O2: BLO1508261JA | P2: BONANZA LOGISTICS | Q2: G03 - Gastos en general | R2: 601 - General de Ley Personas Morales | S2: 6700 | T2: 99 - Por definir | U2: PPD | W2: SERVICIO LOGISTICO: TERRESTRE ORIGEN: CHARLOTTE, NC DESTINO: LAREDO, TX PRO NUMBER: 1118542 OBSERVACIONES: BL25-497 | Y2: 1500 | Z2: 0 | AA2: 0 | AC2: 1500 | AD2: =(Y2*AH2) -> 30762 | AE2: =VLOOKUP(D2,'FACTURAS INGRESOS'!$I$487:$P$718,8,0) -> 30762 | AF2: =AD2-AE2 -> 0 | AG2: USD | AH2: 20.508 | AK2: 1500 | AV2: 1.0000007e+15 | AW2: 1.0000007e+15 | AX2: C:\AdminXML\BovedaCFDi\MME1507071ZA\Emitidas\2025\03\05BF2ED7-0CE4-42C0-B1D6-D2CDCEE44E75@0000000000XX0.xml
D3: 122F9E84-EE04-4C0E-8144-680B4265004C | E3: F | F3: F4474 | G3: 4 | H3: I - Ingreso | I3: 2025-03-04T10:39:17 | J3: 2025-03-04T10:38:10 | K3: 66260 | L3: MME1507071ZA | M3: MILLHOUSE MEXICO | N3: 601 - General de Ley Personas Morales | O3: CPM1604014I1 | P3: CHASE PLASTICS DE MEXICO | Q3: G03 - Gastos en general | R3: 601 - General de Ley Personas Morales | S3: 6500 | T3: 99 - Por definir | U3: PPD | W3: SERVICIO LOGISTICO: TERRESTRE ORIGEN: EL MARQUÉS, QA DESTINO: SAN LUIS POTOSÍ, SL PRO NUMBER: 1119262 OBSERVACIONES: 2536225 / A. Raymond / 1477670 | Y3: 14000 | Z3: 0 | AA3: 2240 | AC3: 16240 | AD3: =Y3*AH3 -> 14000 | AE3: =VLOOKUP(D3,'FACTURAS INGRESOS'!$I$487:$P$718,8,0) -> 14000 | AF3: =AD3-AE3 -> 0 | AG3: MXN | AH3: 1 | AM3: 2240 | AV3: 1.0000007e+15 | AW3: 1.0000007e+15 | AX3: C:\AdminXML\BovedaCFDi\MME1507071ZA\Emitidas\2025\03\122F9E84-EE04-4C0E-8144-680B4265004C@0000000000XX0.xml
D4: FC252273-884E-4ADB-BE50-A2D6333E40F3 | E4: F | F4: F4475 | G4: 4 | H4: I - Ingreso | I4: 2025-03-04T10:40:47 | J4: 2025-03-04T10:39:40 | K4: 66260 | L4: MME1507071ZA | M4: MILLHOUSE MEXICO | N4: 601 - General de Ley Personas Morales | O4: CPM1604014I1 | P4: CHASE PLASTICS DE MEXICO | Q4: G03 - Gastos en general | R4: 601 - General de Ley Personas Morales | S4: 6500 | T4: 99 - Por definir | U4: PPD | W4: SERVICIO LOGISTICO: TERRESTRE ORIGEN: EL MARQUÉS, QA DESTINO: SILAO CENTRO, GJ PRO NUMBER: 1119654 OBSERVACIONES: 2536351 / Technimark / 1466030 | Y4: 16500 | Z4: 0 | AA4: 2640 | AC4: 19140 | AD4: =Y4*AH4 -> 16500 | AE4: =VLOOKUP(D4,'FACTURAS INGRESOS'!$I$487:$P$718,8,0) -> 16500 | AF4: =AD4-AE4 -> 0 | AG4: MXN | AH4: 1 | AM4: 2640 | AV4: 1.0000007e+15 | AW4: 1.0000007e+15 | AX4: C:\AdminXML\BovedaCFDi\MME1507071ZA\Emitidas\2025\03\FC252273-884E-4ADB-BE50-A2D6333E40F3@0000000000XX0.xml
D5: E6BA7F42-1BBC-4756-8688-B4A4AA7313EE | E5: F | F5: F4476 | G5: 4 | H5: I - Ingreso | I5: 2025-03-04T10:42:25 | J5: 2025-03-04T10:41:14 | K5: 66260 | L5: MME1507071ZA | M5: MILLHOUSE MEXICO | N5: 601 - General de Ley Personas Morales | O5: CPM1604014I1 | P5: CHASE PLASTICS DE MEXICO | Q5: G03 - Gastos en general | R5: 601 - General de Ley Personas Morales | S5: 6500 | T5: 99 - Por definir | U5: PPD | W5: SERVICIO LOGISTICO: TERRESTRE ORIGEN: EL MARQUÉS, QA DESTINO: COLONIA MÉXICO, QA PRO NUMBER: 1119659 OBSERVACIONES: 2536350 / GLN / 1479923 | Y5: 5000 | Z5: 0 | AA5: 800 | AC5: 5800 | AD5: =Y5*AH5 -> 5000 | AE5: =VLOOKUP(D5,'FACTURAS INGRESOS'!$I$487:$P$718,8,0) -> 5000 | AF5: =AD5-AE5 -> 0 | AG5: MXN | AH5: 1 | AM5: 800 | AV5: 1.0000007e+15 | AW5: 1.0000007e+15 | AX5: C:\AdminXML\BovedaCFDi\MME1507071ZA\Emitidas\2025\03\E6BA7F42-1BBC-4756-8688-B4A4AA7313EE@0000000000XX0.xml
D6: B2F3D698-A2FE-4186-97A7-C7808DDCFA8E | E6: F | F6: F4477 | G6: 4 | H6: I - Ingreso | I6: 2025-03-04T10:43:54 | J6: 2025-03-04T10:42:52 | K6: 66260 | L6: MME1507071ZA | M6: MILLHOUSE MEXICO | N6: 601 - General de Ley Personas Morales | O6: CPM1604014I1 | P6: CHASE PLASTICS DE MEXICO | Q6: G03 - Gastos en general | R6: 601 - General de Ley Personas Morales | S6: 6500 | T6: 99 - Por definir | U6: PPD | W6: SERVICIO LOGISTICO: TERRESTRE ORIGEN: APODACA CENTRO, NX DESTINO: EL MARQUÉS, QA PRO NUMBER: 1119663 OBSERVACIONES: BOL#: 2505200051 / PO# 5175007 | Y6: 27000 | Z6: 0 | AA6: 4320 | AC6: 31320 | AD6: =Y6*AH6 -> 27000 | AE6: =VLOOKUP(D6,'FACTURAS INGRESOS'!$I$487:$P$718,8,0) -> 27000 | AF6: =AD6-AE6 -> 0 | AG6: MXN | AH6: 1 | AM6: 4320 | AV6: 1.0000007e+15 | AW6: 1.0000007e+15 | AX6: C:\AdminXML\BovedaCFDi\MME1507071ZA\Emitidas\2025\03\B2F3D698-A2FE-4186-97A7-C7808DDCFA8E@0000000000XX0.xml
D7: 853575CE-C4D9-4A42-B717-1F773030BE2C | E7: F | F7: F4478 | G7: 4 | H7: I - Ingreso | I7: 2025-03-04T10:45:55 | J7: 2025-03-04T10:44:22 | K7: 66260 | L7: MME1507071ZA | M7: MILLHOUSE MEXICO | N7: 601 - General de Ley Personas Morales | O7: CPM1604014I1 | P7: CHASE PLASTICS DE MEXICO | Q7: G03 - Gastos en general | R7: 601 - General de Ley Personas Morales | S7: 6500 | T7: 99 - Por definir | U7: PPD | W7: SERVICIO LOGISTICO: TERRESTRE ORIGEN: EL MARQUÉS, QA DESTINO: BENITO JUÁREZ, QA PRO NUMBER: 1120270 OBSERVACIONES: Folio: OSQRO-6564 | Y7: 6000 | Z7: 0 | AA7: 960 | AC7: 6960 | AD7: =Y7*AH7 -> 6000 | AE7: =VLOOKUP(D7,'FACTURAS INGRESOS'!$I$487:$P$718,8,0) -> 6000 | AF7: =AD7-AE7 -> 0 | AG7: MXN | AH7: 1 | AM7: 960 | AV7: 1.0000007e+15 | AW7: 1.0000007e+15 | AX7: C:\AdminXML\BovedaCFDi\MME1507071ZA\Emitidas\2025\03\853575CE-C4D9-4A42-B717-1F773030BE2C@0000000000XX0.xml
D8: AB32F709-6BD6-4490-8602-AAE700F13CF4 | E8: F | F8: F4479 | G8: 4 | H8: I - Ingreso | I8: 2025-03-04T10:57:18 | J8: 2025-03-04T10:55:20 | K8: 66260 | L8: MME1507071ZA | M8: MILLHOUSE MEXICO | N8: 601 - General de Ley Personas Morales | O8: IMG860612JKA | P8: INGENIERIA Y MAQUINARIA DE GUADALUPE | Q8: G03 - Gastos en general | R8: 601 - General de Ley Personas Morales | S8: 25870 | T8: 99 - Por definir | U8: PPD | W8: SERVICIO LOGISTICO: MARITIMO ORIGEN: DENAMARK, XX DESTINO: CASTAÑOS CENTRO, CU PRO NUMBER: 1060077 OBSERVACIONES: OC2024007401A | Y8: 1642 | Z8: 0 | AA8: 0 | AC8: 1642 | AD8: =Y8*AH8 -> 33674.136 | AE8: =VLOOKUP(D8,'FACTURAS INGRESOS'!$I$487:$P$718,8,0) -> #N/A | AF8: =AD8-AE8 -> #N/A | AG8: USD | AH8: 20.508 | AK8: 1642 | AV8: 1.0000007e+15 | AW8: 1.0000007e+15 | AX8: C:\AdminXML\BovedaCFDi\MME1507071ZA\Emitidas\2025\03\AB32F709-6BD6-4490-8602-AAE700F13CF4@0000000000XX0.xml
D9: 615BD083-D710-42B0-A80F-767A81B049DB | E9: F | F9: F4480 | G9: 4 | H9: I - Ingreso | I9: 2025-03-04T11:02:18 | J9: 2025-03-04T11:01:14 | K9: 66260 | L9: MME1507071ZA | M9: MILLHOUSE MEXICO | N9: 601 - General de Ley Personas Morales | O9: CFM970129RG7 | P9: CEVA FREIGHT MANAGEMENT MEXICO | Q9: G03 - Gastos en general | R9: 601 - General de Ley Personas Morales | S9: 3720 | T9: 99 - Por definir | U9: PPD | W9: SERVICIO LOGISTICO: TERRESTRE ORIGEN: MANZANILLO, CL DESTINO: CHIHUAHUA, CI PRO NUMBER: 1120844 OBSERVACIONES: 1443820009816 | Y9: 53800 | Z9: 0 | AA9: 8608 | AC9: 62408 | AD9: =Y9*AH9 -> 53800 | AE9: =VLOOKUP(D9,'FACTURAS INGRESOS'!$I$487:$P$718,8,0) -> 53800 | AF9: =AD9-AE9 -> 0 | AG9: MXN | AH9: 1 | AM9: 8608 | AV9: 1.0000007e+15 | AW9: 1.0000007e+15 | AX9: C:\AdminXML\BovedaCFDi\MME1507071ZA\Emitidas\2025\03\615BD083-D710-42B0-A80F-767A81B049DB@0000000000XX0.xml
D10: 7F70E0F5-E3B5-41D8-A85E-4CECD2BBBC49 | E10: F | F10: F4481 | G10: 4 | H10: I - Ingreso | I10: 2025-03-04T11:03:54 | J10: 2025-03-04T11:02:47 | K10: 66260 | L10: MME1507071ZA | M10: MILLHOUSE MEXICO | N10: 601 - General de Ley Personas Morales | O10: CPM1604014I1 | P10: CHASE PLASTICS DE MEXICO | Q10: G03 - Gastos en general | R10: 601 - General de Ley Personas Morales | S10: 6500 | T10: 99 - Por definir | U10: PPD | W10: SERVICIO LOGISTICO: TERRESTRE ORIGEN: APODACA CENTRO, NX DESTINO: IZTAPALAPA, DF PRO NUMBER: 1120300 OBSERVACIONES: 1476984 / Vinoplastic / OCQ10426 | Y10: 21000 | Z10: 0 | AA10: 3360 | AC10: 24360 | AD10: =Y10*AH10 -> 21000 | AE10: =VLOOKUP(D10,'FACTURAS INGRESOS'!$I$487:$P$718,8,0) -> 21000 | AF10: =AD10-AE10 -> 0 | AG10: MXN | AH10: 1 | AM10: 3360 | AV10: 1.0000007e+15 | AW10: 1.0000007e+15 | AX10: C:\AdminXML\BovedaCFDi\MME1507071ZA\Emitidas\2025\03\7F70E0F5-E3B5-41D8-A85E-4CECD2BBBC49@0000000000XX0.xml
D11: E2045665-7B12-4CC7-9B28-9502DE3C6DC2 | E11: F | F11: F4482 | G11: 4 | H11: I - Ingreso | I11: 2025-03-04T11:05:12 | J11: 2025-03-04T11:04:18 | K11: 66260 | L11: MME1507071ZA | M11: MILLHOUSE MEXICO | N11: 601 - General de Ley Personas Morales | O11: CTU940107CK8 | P11: CLUB TURAVIA | Q11: G03 - Gastos en general | R11: 601 - General de Ley Personas Morales | S11: 77500 | T11: 99 - Por definir | U11: PPD | W11: REPORTE DE COMISIONES ORIGEN: NA DESTINO: NA PRO NUMBER: NA OBSERVACIONES: NA | Y11: 1198.21 | Z11: 0 | AA11: 191.71 | AC11: 1389.92 | AD11: =Y11*AH11 -> 1198.21 | AE11: =VLOOKUP(D11,'FACTURAS INGRESOS'!$I$487:$P$718,8,0) -> 1198.21 | AF11: =AD11-AE11 -> 0 | AG11: MXN | AH11: 1 | AM11: 191.71 | AV11: 1.0000007e+15 | AW11: 1.0000007e+15 | AX11: C:\AdminXML\BovedaCFDi\MME1507071ZA\Emitidas\2025\03\E2045665-7B12-4CC7-9B28-9502DE3C6DC2@0000000000XX0.xml
D12: F42C0258-7A71-4B46-9FFC-CF3B76082FD6 | E12: F | F12: F4483 | G12: 4 | H12: I - Ingreso | I12: 2025-03-04T11:06:32 | J12: 2025-03-04T11:05:38 | K12: 66260 | L12: MME1507071ZA | M12: MILLHOUSE MEXICO | N12: 601 - General de Ley Personas Morales | O12: CFO030723285 | P12: CONTINENTE FORWARDING | Q12: G03 - Gastos en general | R12: 601 - General de Ley Personas Morales | S12: 66260 | T12: 99 - Por definir | U12: PPD | W12: SERVICIO LOGISTICO: TERRESTRE ORIGEN: ERIE, PA DESTINO: LAREDO, TX PRO NUMBER: 1120864 OBSERVACIONES: C45695 | Y12: 1925 | Z12: 0 | AA12: 0 | AC12: 1925 | AD12: =Y12*AH12 -> 39477.9 | AE12: =VLOOKUP(D12,'FACTURAS INGRESOS'!$I$487:$P$718,8,0) -> 39477.9 | AF12: =AD12-AE12 -> 0 | AG12: USD | AH12: 20.508 | AK12: 1925 | AV12: 1.0000007e+15 | AW12: 1.0000007e+15 | AX12: C:\AdminXML\BovedaCFDi\MME1507071ZA\Emitidas\2025\03\F42C0258-7A71-4B46-9FFC-CF3B76082FD6@0000000000XX0.xml
D13: 2C44C0D2-DD27-4586-98BB-481DF28AC6A4 | E13: F | F13: F4484 | G13: 4 | H13: I - Ingreso | I13: 2025-03-04T11:08:27 | J13: 2025-03-04T11:07:27 | K13: 66260 | L13: MME1507071ZA | M13: MILLHOUSE MEXICO | N13: 601 - General de Ley Personas Morales | O13: CFO030723285 | P13: CONTINENTE FORWARDING | Q13: G03 - Gastos en general | R13: 601 - General de Ley Personas Morales | S13: 66260 | T13: 99 - Por definir | U13: PPD | W13: SERVICIO LOGISTICO: TERRESTRE ORIGEN: MILWAUKEE, WI DESTINO: MILWAUKEE, WI PRO NUMBER: 1120945 OBSERVACIONES: C45726 | Y13: 1700 | Z13: 0 | AA13: 0 | AC13: 1700 | AD13: =Y13*AH13 -> 34863.6 | AE13: =VLOOKUP(D13,'FACTURAS INGRESOS'!$I$487:$P$718,8,0) -> 34863.6 | AF13: =AD13-AE13 -> 0 | AG13: USD | AH13: 20.508 | AK13: 1700 | AV13: 1.0000007e+15 | AW13: 1.0000007e+15 | AX13: C:\AdminXML\BovedaCFDi\MME1507071ZA\Emitidas\2025\03\2C44C0D2-DD27-4586-98BB-481DF28AC6A4@0000000000XX0.xml
D14: 4CB15B85-AA36-438E-A682-B415221F97F9 | E14: F | F14: F4485 | G14: 4 | H14: I - Ingreso | I14: 2025-03-04T11:09:49 | J14: 2025-03-04T11:08:55 | K14: 66260 | L14: MME1507071ZA | M14: MILLHOUSE MEXICO | N14: 601 - General de Ley Personas Morales | O14: CFO030723285 | P14: CONTINENTE FORWARDING | Q14: G03 - Gastos en general | R14: 601 - General de Ley Personas Morales | S14: 66260 | T14: 99 - Por definir | U14: PPD | W14: SERVICIO LOGISTICO: TERRESTRE ORIGEN: CANTON, MI DESTINO: LAREDO, TX PRO NUMBER: 1121033 OBSERVACIONES: C45798 | Y14: 1765 | Z14: 0 | AA14: 0 | AC14: 1765 | AD14: =Y14*AH14 -> 36196.62 | AE14: =VLOOKUP(D14,'FACTURAS INGRESOS'!$I$487:$P$718,8,0) -> 36196.62 | AF14: =AD14-AE14 -> 0 | AG14: USD | AH14: 20.508 | AK14: 1765 | AV14: 1.0000007e+15 | AW14: 1.0000007e+15 | AX14: C:\AdminXML\BovedaCFDi\MME1507071ZA\Emitidas\2025\03\4CB15B85-AA36-438E-A682-B415221F97F9@0000000000XX0.xml
D15: 1F09ADD4-9324-402D-A563-DC96C6A82D58 | E15: F | F15: F4486 | G15: 4 | H15: I - Ingreso | I15: 2025-03-04T11:11:18 | J15: 2025-03-04T11:10:24 | K15: 66260 | L15: MME1507071ZA | M15: MILLHOUSE MEXICO | N15: 601 - General de Ley Personas Morales | O15: DRO190903817 | P15: DSV ROAD | Q15: G03 - Gastos en general | R15: 601 - General de Ley Personas Morales | S15: 3740 | T15: 99 - Por definir | U15: PPD | W15: SERVICIO LOGISTICO: TERRESTRE ORIGEN: LAREDO, TX DESTINO: HOLLAND, MI PRO NUMBER: 1114633 OBSERVACIONES: SG9L0012735 | Y15: 4100 | Z15: 0 | AA15: 0 | AC15: 4100 | AD15: =Y15*AH15 -> 84082.8 | AE15: =VLOOKUP(D15,'FACTURAS INGRESOS'!$I$487:$P$718,8,0) -> 84082.8 | AF15: =AD15-AE15 -> 0 | AG15: USD | AH15: 20.508 | AK15: 4100 | AV15: 1.0000007e+15 | AW15: 1.0000007e+15 | AX15: C:\AdminXML\BovedaCFDi\MME1507071ZA\Emitidas\2025\03\1F09ADD4-9324-402D-A563-DC96C6A82D58@0000000000XX0.xml
D16: 419487D6-0FE2-4ACF-9CB3-125EF76520D0 | E16: F | F16: F4487 | G16: 4 | H16: I - Ingreso | I16: 2025-03-04T11:12:51 | J16: 2025-03-04T11:11:58 | K16: 66260 | L16: MME1507071ZA | M16: MILLHOUSE MEXICO | N16: 601 - General de Ley Personas Morales | O16: EOP640608I13 | P16: HELLA AUTOMOTIVE MEXICO | Q16: G03 - Gastos en general | R16: 601 - General de Ley Personas Morales | S16: 45601 | T16: 99 - Por definir | U16: PPD | W16: SERVICIO LOGISTICO: TERRESTRE ORIGEN: EL PASO, TX DESTINO: ÁLVAREZ DEL CASTILLO, JA PRO NUMBER: 1117914 OBSERVACIONES: PL6-OV25-INCA1-00408-2753-573040-USD | Y16: 2400 | Z16: 0 | AA16: 0 | AC16: 2400 | AD16: =Y16*AH16 -> 49219.2 | AE16: =VLOOKUP(D16,'FACTURAS INGRESOS'!$I$487:$P$718,8,0) -> 49219.2 | AF16: =AD16-AE16 -> 0 | AG16: USD | AH16: 20.508 | AK16: 2400 | AV16: 1.0000007e+15 | AW16: 1.0000007e+15 | AX16: C:\AdminXML\BovedaCFDi\MME1507071ZA\Emitidas\2025\03\419487D6-0FE2-4ACF-9CB3-125EF76520D0@0000000000XX0.xml
D17: ACF554AC-0EAF-4B25-8F4C-59BF2E7B24E3 | E17: F | F17: F4488 | G17: 4 | H17: I - Ingreso | I17: 2025-03-04T11:14:14 | J17: 2025-03-04T11:13:21 | K17: 66260 | L17: MME1507071ZA | M17: MILLHOUSE MEXICO | N17: 601 - General de Ley Personas Morales | O17: EOP640608I13 | P17: HELLA AUTOMOTIVE MEXICO | Q17: G03 - Gastos en general | R17: 601 - General de Ley Personas Morales | S17: 45601 | T17: 99 - Por definir | U17: PPD | W17: SERVICIO LOGISTICO: TERRESTRE ORIGEN: LAREDO, TX DESTINO: VANCE, AL PRO NUMBER: 1120614 OBSERVACIONES: PL7-OV25-OUTC1-00354-4514-639208-USD | Y17: 3100 | Z17: 0 | AA17: 0 | AC17: 3100 | AD17: =Y17*AH17 -> 63574.8 | AE17: =VLOOKUP(D17,'FACTURAS INGRESOS'!$I$487:$P$718,8,0) -> 63574.8 | AF17: =AD17-AE17 -> 0 | AG17: USD | AH17: 20.508 | AK17: 3100 | AV17: 1.0000007e+15 | AW17: 1.0000007e+15 | AX17: C:\AdminXML\BovedaCFDi\MME1507071ZA\Emitidas\2025\03\ACF554AC-0EAF-4B25-8F4C-59BF2E7B24E3@0000000000XX0.xml
